<?xml version="1.0"?>
<robot xmlns:xacro="http://www.ros.org/wiki/xacro" >
    <xacro:include filename="intertial_macros.xacro"/>

   <material name="white">
        <color rgba="1 1 1 1" />
    </material>

    <material name="orange">
        <color rgba="1 0.3 0.1 1"/>
    </material>

    <material name="blue">
        <color rgba="0.2 0.2 1 1"/>
    </material>

    <material name="black">
        <color rgba="0 0 0 1"/>
    </material>

    <material name="red">
        <color rgba="1 0 0 1"/>
    </material>

    <!-- BASE LINK -->

    <link name="base_link">

    </link>

    <!-- CHASSIS LINK -->

    <joint name="chassis_joint" type="fixed">
        <parent link="base_link"/>
        <child link="chassis"/>
        <origin xyz="-0.1 0 0"/>
    </joint>

    <link name="chassis">
        <visual>
            <origin xyz="0.165 0 0.02"/>
            <geometry>
                <box size="0.33 0.267 0.04"/>
            </geometry>
            <material name="white"/>
        </visual>
        <collision>
            <origin xyz="0.165 0 0.02"/>
            <geometry>
                <box size="0.33 0.267 0.04"/>
            </geometry>
        </collision>
        
        <xacro:inertial_box mass="2" x="0.33" y="0.267" z="0.04">
            <origin xyz="0.165 0 0.02" rpy="0 0 0"/>
        </xacro:inertial_box>
    </link>
    <gazebo reference="chassis">
        <material>Gazebo/White</material>
    </gazebo>
    <!-- LEFT WHEEL LINK -->

    <joint name="left_wheel_joint" type="continuous">
        <parent link="base_link"/>
        <child link="left_wheel"/>
        <origin xyz="0 0.175 0" rpy="-${pi/2} 0 0" />
        <axis xyz="0 0 1"/>
    </joint>
    
    <link name="left_wheel">
        <visual>
            <geometry>
                <cylinder radius="0.051" length="0.044"/>
            </geometry>
            <material name="blue"/>
        </visual>
        <collision>
            <geometry>
                <cylinder radius="0.051" length="0.044"/>
            </geometry>
        </collision>
        <xacro:inertial_cylinder mass="0.2" length="0.044" radius="0.051">
            <origin xyz="0 0 0" rpy="0 0 0"/>
        </xacro:inertial_cylinder>
    </link>
    <gazebo reference="left_wheel">
        <material>Gazebo/Blue</material>
    </gazebo>

    <!-- RIGHT WHEEL LINK -->

    <joint name="right_wheel_joint" type="continuous">
        <parent link="base_link"/>
        <child link="right_wheel"/>
        <origin xyz="0 -0.175 0" rpy="${pi/2} 0 0" />
        <axis xyz="0 0 -1"/>
    </joint>
    
    <link name="right_wheel">
        <visual>
            <geometry>
                <cylinder radius="0.051" length="0.044"/>
            </geometry>
            <material name="blue"/>
        </visual>
        <collision>
            <geometry>
                <cylinder radius="0.051" length="0.044"/>
            </geometry>
        </collision>
        <xacro:inertial_cylinder mass="0.2" length="0.044" radius="0.051">
            <origin xyz="0 0 0" rpy="0 0 0"/>
        </xacro:inertial_cylinder>
    </link>
    <gazebo reference="right_wheel">
        <material>Gazebo/Blue</material>
    </gazebo>

    <!-- FRONT CASTER WHEELS -->

        <!-- LEFT WHEEL LINK -->
        
        <joint name="caster_left_joint" type="fixed">
            <parent link="base_link"/>
            <child link="caster_left_wheel"/>
            <origin xyz="0.18 0.175 0" rpy="-${pi/2} 0 0" />
            <axis xyz="0 0 1"/>
        </joint>
        
        <link name="caster_left_wheel">
            <visual>
                <geometry>
                    <cylinder radius="0.051" length="0.044"/>
                </geometry>
                <material name="blue"/>
            </visual>
            <collision>
                <geometry>
                    <cylinder radius="0.051" length="0.044"/>
                </geometry>
            </collision>
            <xacro:inertial_cylinder mass="0.2" length="0.044" radius="0.051">
            <origin xyz="0 0 0" rpy="0 0 0"/>
            </xacro:inertial_cylinder>
        </link>
        <gazebo reference="caster_left_wheel">
            <material>Gazebo/Blue</material>
            <mu1 value="0.001"/>
            <mu2 value="0.001"/>
        </gazebo>

        <!-- RIGHT WHEEL LINK -->

        <joint name="caster_right_joint" type="fixed">
            <parent link="base_link"/>
            <child link="caster_right_wheel"/>
            <origin xyz="0.18 -0.175 0" rpy="${pi/2} 0 0" />
            <axis xyz="0 0 -1"/>
        </joint>
        
        <link name="caster_right_wheel">
            <visual>
                <geometry>
                    <cylinder radius="0.051" length="0.044"/>
                </geometry>
                <material name="blue"/>
            </visual>
            <collision>
                <geometry>
                    <cylinder radius="0.051" length="0.044"/>
                </geometry>
            </collision>
            <xacro:inertial_cylinder mass="0.2" length="0.044" radius="0.051">
            <origin xyz="0 0 0" rpy="0 0 0"/>
            </xacro:inertial_cylinder>
        </link>
        <gazebo reference="caster_right_wheel">
            <material>Gazebo/Blue</material>
            <mu1 value="0.001"/>
            <mu2 value="0.001"/>
        </gazebo>
</robot>